Workbook

Sheet 대시보드
A1: 품목별 원가 비교 대시보드
A2: ="브랜드: "&설정!$C$4&" | 기준 시즌: "&설정!$C$15&" "&설정!$C$16&" (설정 시트에서 변경)" -> 브랜드: 브랜드A | 기준 시즌: 2026 FW (설정 시트에서 변경)

Sheet 설정
A1: 기본 설정
A2: 노란색 칸만 수정하세요. 모든 표와 차트가 이 값을 따라 바뀝니다.
B4: 브랜드 | C4: 브랜드A | D4: RawData 시트의 브랜드명과 똑같이 입력
B5: 년도 1 | C5: 2025
B6: 년도 2 | C6: 2026
B7: 시즌 1 | C7: SS
B8: 시즌 2 | C8: FW
B9: 품목 1 | C9: 아우터
B10: 품목 2 | C10: 니트
B11: 품목 3 | C11: 셔츠
B12: 품목 4 | C12: 팬츠
B13: 품목 5 | C13: 스커트
B14: 품목 6 | C14: 원피스
B15: 기준 년도 (차트용) | C15: 2026 | D15: ← 목록에서 선택 (구성비·전년대비 차트 기준)
B16: 기준 시즌 (차트용) | C16: FW | D16: ← 목록에서 선택

Sheet RawData
A1: 원가 원본 데이터 (스타일 1개 = 1행)
A2: ※ 현재는 가상 데이터입니다. 내일 4행부터 실제 데이터를 붙여넣으면(기존 행 삭제 후) 비교표·차트가 자동으로 바뀝니다. 행 수 제한 없음. 단위: 원
A3: 브랜드 | B3: 년도 | C3: 시즌 | D3: 품목 | E3: 스타일번호 | F3: 원자재 | G3: 부자재 | H3: 가공임 | J3: 입력 규칙
A4: 브랜드A | B4: 2025 | C4: SS | D4: 아우터 | E4: 25SS-0101 | F4: 52100 | G4: 7200 | H4: 24200 | J4: • 브랜드: 설정 시트 브랜드명과 동일
A5: 브랜드A | B5: 2025 | C5: SS | D5: 아우터 | E5: 25SS-0102 | F5: 49900 | G5: 6100 | H5: 28700 | J5: • 년도: 숫자 (예: 2026)
A6: 브랜드A | B6: 2025 | C6: SS | D6: 아우터 | E6: 25SS-0103 | F6: 51400 | G6: 6600 | H6: 24500 | J6: • 시즌: SS 또는 FW (설정 시트와 동일)
A7: 브랜드A | B7: 2025 | C7: SS | D7: 아우터 | E7: 25SS-0104 | F7: 42800 | G7: 6700 | H7: 28400 | J7: • 품목: 설정 시트의 6개 품목명과 동일
A8: 브랜드A | B8: 2025 | C8: SS | D8: 아우터 | E8: 25SS-0105 | F8: 36400 | G8: 7900 | H8: 31800 | J8: • 원자재/부자재/가공임: 숫자 (원)
A9: 브랜드A | B9: 2025 | C9: SS | D9: 아우터 | E9: 25SS-0106 | F9: 46500 | G9: 8000 | H9: 24300 | J9: • 예시 행: 브랜드A | 2026 | FW | 아우터 | 26FW-0101 | 61,200 | 10,400 | 29,700
A10: 브랜드A | B10: 2025 | C10: SS | D10: 아우터 | E10: 25SS-0107 | F10: 45700 | G10: 5900 | H10: 25700
A11: 브랜드A | B11: 2025 | C11: SS | D11: 아우터 | E11: 25SS-0108 | F11: 45200 | G11: 6200 | H11: 27300
A12: 브랜드A | B12: 2025 | C12: SS | D12: 아우터 | E12: 25SS-0109 | F12: 44900 | G12: 7900 | H12: 28500
A13: 브랜드A | B13: 2025 | C13: SS | D13: 아우터 | E13: 25SS-0110 | F13: 47400 | G13: 6100 | H13: 28600
A14: 브랜드A | B14: 2025 | C14: SS | D14: 니트 | E14: 25SS-0201 | F14: 16900 | G14: 2600 | H14: 10400
A15: 브랜드A | B15: 2025 | C15: SS | D15: 니트 | E15: 25SS-0202 | F15: 14700 | G15: 2200 | H15: 12600
A16: 브랜드A | B16: 2025 | C16: SS | D16: 니트 | E16: 25SS-0203 | F16: 17300 | G16: 2300 | H16: 12300
A17: 브랜드A | B17: 2025 | C17: SS | D17: 니트 | E17: 25SS-0204 | F17: 17500 | G17: 2300 | H17: 13100
A18: 브랜드A | B18: 2025 | C18: SS | D18: 니트 | E18: 25SS-0205 | F18: 19300 | G18: 2200 | H18: 12300
A19: 브랜드A | B19: 2025 | C19: SS | D19: 니트 | E19: 25SS-0206 | F19: 18000 | G19: 3000 | H19: 12800
A20: 브랜드A | B20: 2025 | C20: SS | D20: 니트 | E20: 25SS-0207 | F20: 16300 | G20: 3200 | H20: 10600
A21: 브랜드A | B21: 2025 | C21: SS | D21: 니트 | E21: 25SS-0208 | F21: 17300 | G21: 2900 | H21: 10700
... A247: 브랜드A | B247: 2026 | C247: FW | D247: 원피스 | E247: 26FW-0612 | F247: 18600 | G247: 6000 | H247: 12600

Sheet 피벗
A1: 피벗 테이블 (RawData 기반)
A4: 필터
A5: 브랜드 | B5: (모두)
D7: Data
A8: 년도 | B8: 시즌 | C8: 품목 | D8: 평균 : 원자재 | E8: 평균 : 부자재 | F8: 평균 : 가공임
A9: 2025 | B9: FW | C9: 니트 | D9: 23683.333 | E9: 3733.3333 | F9: 11575
C10: 셔츠 | D10: 13011.111 | E10: 2977.7778 | F10: 7966.6667
C11: 스커트 | D11: 14037.5 | E11: 3212.5 | F11: 8450
C12: 아우터 | D12: 57677.778 | E12: 11811.111 | F12: 26966.667
C13: 원피스 | D13: 21408.333 | E13: 4233.3333 | F13: 12758.333
C14: 팬츠 | D14: 16110 | E14: 4120 | F14: 9230
B15: SS | C15: 니트 | D15: 17233.333 | E15: 2522.2222 | F15: 11933.333
C16: 셔츠 | D16: 9666.6667 | E16: 2158.3333 | F16: 7858.3333
C17: 스커트 | D17: 10050 | E17: 2433.3333 | F17: 8000
C18: 아우터 | D18: 46230 | E18: 6860 | F18: 27200
C19: 원피스 | D19: 15755.556 | E19: 3400 | F19: 13166.667
C20: 팬츠 | D20: 12236.364 | E20: 2954.5455 | F20: 9272.7273
A21: 2026 | B21: FW | C21: 니트 | D21: 24177.778 | E21: 3666.6667 | F21: 13000
C22: 셔츠 | D22: 13450 | E22: 3200 | F22: 8662.5
C23: 스커트 | D23: 13512.5 | E23: 3625 | F23: 8925
C24: 아우터 | D24: 62854.545 | E24: 10690.909 | F24: 30563.636
C25: 원피스 | D25: 22116.667 | E25: 4766.6667 | F25: 13458.333
C26: 팬츠 | D26: 16700 | E26: 4244.4444 | F26: 9933.3333
B27: SS | C27: 니트 | D27: 18700 | E27: 2640 | F27: 12130
C28: 셔츠 | D28: 10241.667 | E28: 2158.3333 | F28: 8833.3333
C29: 스커트 | D29: 10275 | E29: 2708.3333 | F29: 9258.3333
C30: 아우터 | D30: 46608.333 | E30: 7625 | F30: 29891.667
C31: 원피스 | D31: 17150 | E31: 3412.5 | F31: 13475
C32: 팬츠 | D32: 12870 | E32: 3170 | F32: 9890
A33: Total Result | D33: 22048.77 | E33: 4266.3934 | F33: 13545.492

Sheet 비교표
A1: 년도·시즌·품목별 평균 원가 비교표
A2: ="브랜드: "&설정!$C$4&" | 단위: 원 (스타일 평균)" -> 브랜드: 브랜드A | 단위: 원 (스타일 평균)
A4: 년도 | B4: 시즌 | C4: 년도시즌 | D4: 품목 | E4: 스타일수 | F4: 원자재 | G4: 부자재 | H4: 가공임 | I4: 총원가 | J4: 원자재 비중 | K4: 부자재 비중 | L4: 가공임 비중
A5: =설정!$C$5 -> 2025 | B5: =설정!$C$7 -> SS | C5: =A5&" "&B5 -> 2025 SS | D5: =설정!$C$9 -> 아우터 | E5: =COUNTIFS(RawData!$A:$A,설정!$C$4,RawData!$B:$B,$A5,RawData!$C:$C,$B5,RawData!$D:$D,$D5) -> 10 | F5: =IFERROR(AVERAGEIFS(RawData!$F:$F,RawData!$A:$A,설정!$C$4,RawData!$B:$B,$A5,RawData!$C:$C,$B5,RawData!$D:$D,$D5),0) -> 46230 | G5: =IFERROR(AVERAGEIFS(RawData!$G:$G,RawData!$A:$A,설정!$C$4,RawData!$B:$B,$A5,RawData!$C:$C,$B5,RawData!$D:$D,$D5),0) -> 6860 | H5: =IFERROR(AVERAGEIFS(RawData!$H:$H,RawData!$A:$A,설정!$C$4,RawData!$B:$B,$A5,RawData!$C:$C,$B5,RawData!$D:$D,$D5),0) -> 27200 | I5: =SUM(F5:H5) -> 80290 | J5: =IF($I5=0,0,F5/$I5) -> 0.57578777 | K5: =IF($I5=0,0,G5/$I5) -> 0.085440279 | L5: =IF($I5=0,0,H5/$I5) -> 0.33877195
A6: =설정!$C$5 -> 2025 | B6: =설정!$C$7 -> SS | C6: =A6&" "&B6 -> 2025 SS | D6: =설정!$C$10 -> 니트 | E6: =COUNTIFS(RawData!$A:$A,설정!$C$4,RawData!$B:$B,$A6,RawData!$C:$C,$B6,RawData!$D:$D,$D6) -> 9 | F6: =IFERROR(AVERAGEIFS(RawData!$F:$F,RawData!$A:$A,설정!$C$4,RawData!$B:$B,$A6,RawData!$C:$C,$B6,RawData!$D:$D,$D6),0) -> 17233.333 | G6: =IFERROR(AVERAGEIFS(RawData!$G:$G,RawData!$A:$A,설정!$C$4,RawData!$B:$B,$A6,RawData!$C:$C,$B6,RawData!$D:$D,$D6),0) -> 2522.2222 | H6: =IFERROR(AVERAGEIFS(RawData!$H:$H,RawData!$A:$A,설정!$C$4,RawData!$B:$B,$A6,RawData!$C:$C,$B6,RawData!$D:$D,$D6),0) -> 11933.333 | I6: =SUM(F6:H6) -> 31688.889 | J6: =IF($I6=0,0,F6/$I6) -> 0.54382889 | K6: =IF($I6=0,0,G6/$I6) -> 0.079593268 | L6: =IF($I6=0,0,H6/$I6) -> 0.37657784
A7: =설정!$C$5 -> 2025 | B7: =설정!$C$7 -> SS | C7: =A7&" "&B7 -> 2025 SS | D7: =설정!$C$11 -> 셔츠 | E7: =COUNTIFS(RawData!$A:$A,설정!$C$4,RawData!$B:$B,$A7,RawData!$C:$C,$B7,RawData!$D:$D,$D7) -> 12 | F7: =IFERROR(AVERAGEIFS(RawData!$F:$F,RawData!$A:$A,설정!$C$4,RawData!$B:$B,$A7,RawData!$C:$C,$B7,RawData!$D:$D,$D7),0) -> 9666.6667 | G7: =IFERROR(AVERAGEIFS(RawData!$G:$G,RawData!$A:$A,설정!$C$4,RawData!$B:$B,$A7,RawData!$C:$C,$B7,RawData!$D:$D,$D7),0) -> 2158.3333 | H7: =IFERROR(AVERAGEIFS(RawData!$H:$H,RawData!$A:$A,설정!$C$4,RawData!$B:$B,$A7,RawData!$C:$C,$B7,RawData!$D:$D,$D7),0) -> 7858.3333 | I7: =SUM(F7:H7) -> 19683.333 | J7: =IF($I7=0,0,F7/$I7) -> 0.49110923 | K7: =IF($I7=0,0,G7/$I7) -> 0.10965284 | L7: =IF($I7=0,0,H7/$I7) -> 0.39923793
A8: =설정!$C$5 -> 2025 | B8: =설정!$C$7 -> SS | C8: =A8&" "&B8 -> 2025 SS | D8: =설정!$C$12 -> 팬츠 | E8: =COUNTIFS(RawData!$A:$A,설정!$C$4,RawData!$B:$B,$A8,RawData!$C:$C,$B8,RawData!$D:$D,$D8) -> 11 | F8: =IFERROR(AVERAGEIFS(RawData!$F:$F,RawData!$A:$A,설정!$C$4,RawData!$B:$B,$A8,RawData!$C:$C,$B8,RawData!$D:$D,$D8),0) -> 12236.364 | G8: =IFERROR(AVERAGEIFS(RawData!$G:$G,RawData!$A:$A,설정!$C$4,RawData!$B:$B,$A8,RawData!$C:$C,$B8,RawData!$D:$D,$D8),0) -> 2954.5455 | H8: =IFERROR(AVERAGEIFS(RawData!$H:$H,RawData!$A:$A,설정!$C$4,RawData!$B:$B,$A8,RawData!$C:$C,$B8,RawData!$D:$D,$D8),0) -> 9272.7273 | I8: =SUM(F8:H8) -> 24463.636 | J8: =IF($I8=0,0,F8/$I8) -> 0.5001858 | K8: =IF($I8=0,0,G8/$I8) -> 0.12077295 | L8: =IF($I8=0,0,H8/$I8) -> 0.37904125
A9: =설정!$C$5 -> 2025 | B9: =설정!$C$7 -> SS | C9: =A9&" "&B9 -> 2025 SS | D9: =설정!$C$13 -> 스커트 | E9: =COUNTIFS(RawData!$A:$A,설정!$C$4,RawData!$B:$B,$A9,RawData!$C:$C,$B9,RawData!$D:$D,$D9) -> 12 | F9: =IFERROR(AVERAGEIFS(RawData!$F:$F,RawData!$A:$A,설정!$C$4,RawData!$B:$B,$A9,RawData!$C:$C,$B9,RawData!$D:$D,$D9),0) -> 10050 | G9: =IFERROR(AVERAGEIFS(RawData!$G:$G,RawData!$A:$A,설정!$C$4,RawData!$B:$B,$A9,RawData!$C:$C,$B9,RawData!$D:$D,$D9),0) -> 2433.3333 | H9: =IFERROR(AVERAGEIFS(RawData!$H:$H,RawData!$A:$A,설정!$C$4,RawData!$B:$B,$A9,RawData!$C:$C,$B9,RawData!$D:$D,$D9),0) -> 8000 | I9: =SUM(F9:H9) -> 20483.333 | J9: =IF($I9=0,0,F9/$I9) -> 0.4906428 | K9: =IF($I9=0,0,G9/$I9) -> 0.11879577 | L9: =IF($I9=0,0,H9/$I9) -> 0.39056143
A10: =설정!$C$5 -> 2025 | B10: =설정!$C$7 -> SS | C10: =A10&" "&B10 -> 2025 SS | D10: =설정!$C$14 -> 원피스 | E10: =COUNTIFS(RawData!$A:$A,설정!$C$4,RawData!$B:$B,$A10,RawData!$C:$C,$B10,RawData!$D:$D,$D10) -> 9 | F10: =IFERROR(AVERAGEIFS(RawData!$F:$F,RawData!$A:$A,설정!$C$4,RawData!$B:$B,$A10,RawData!$C:$C,$B10,RawData!$D:$D,$D10),0) -> 15755.556 | G10: =IFERROR(AVERAGEIFS(RawData!$G:$G,RawData!$A:$A,설정!$C$4,RawData!$B:$B,$A10,RawData!$C:$C,$B10,RawData!$D:$D,$D10),0) -> 3400 | H10: =IFERROR(AVERAGEIFS(RawData!$H:$H,RawData!$A:$A,설정!$C$4,RawData!$B:$B,$A10,RawData!$C:$C,$B10,RawData!$D:$D,$D10),0) -> 13166.667 | I10: =SUM(F10:H10) -> 32322.222 | J10: =IF($I10=0,0,F10/$I10) -> 0.48745273 | K10: =IF($I10=0,0,G10/$I10) -> 0.10519079 | L10: =IF($I10=0,0,H10/$I10) -> 0.40735648
A11: =설정!$C$5 -> 2025 | B11: =설정!$C$8 -> FW | C11: =A11&" "&B11 -> 2025 FW | D11: =설정!$C$9 -> 아우터 | E11: =COUNTIFS(RawData!$A:$A,설정!$C$4,RawData!$B:$B,$A11,RawData!$C:$C,$B11,RawData!$D:$D,$D11) -> 9 | F11: =IFERROR(AVERAGEIFS(RawData!$F:$F,RawData!$A:$A,설정!$C$4,RawData!$B:$B,$A11,RawData!$C:$C,$B11,RawData!$D:$D,$D11),0) -> 57677.778 | G11: =IFERROR(AVERAGEIFS(RawData!$G:$G,RawData!$A:$A,설정!$C$4,RawData!$B:$B,$A11,RawData!$C:$C,$B11,RawData!$D:$D,$D11),0) -> 11811.111 | H11: =IFERROR(AVERAGEIFS(RawData!$H:$H,RawData!$A:$A,설정!$C$4,RawData!$B:$B,$A11,RawData!$C:$C,$B11,RawData!$D:$D,$D11),0) -> 26966.667 | I11: =SUM(F11:H11) -> 96455.556 | J11: =IF($I11=0,0,F11/$I11) -> 0.59797258 | K11: =IF($I11=0,0,G11/$I11) -> 0.12245133 | L11: =IF($I11=0,0,H11/$I11) -> 0.27957609
A12: =설정!$C$5 -> 2025 | B12: =설정!$C$8 -> FW | C12: =A12&" "&B12 -> 2025 FW | D12: =설정!$C$10 -> 니트 | E12: =COUNTIFS(RawData!$A:$A,설정!$C$4,RawData!$B:$B,$A12,RawData!$C:$C,$B12,RawData!$D:$D,$D12) -> 12 | F12: =IFERROR(AVERAGEIFS(RawData!$F:$F,RawData!$A:$A,설정!$C$4,RawData!$B:$B,$A12,RawData!$C:$C,$B12,RawData!$D:$D,$D12),0) -> 23683.333 | G12: =IFERROR(AVERAGEIFS(RawData!$G:$G,RawData!$A:$A,설정!$C$4,RawData!$B:$B,$A12,RawData!$C:$C,$B12,RawData!$D:$D,$D12),0) -> 3733.3333 | H12: =IFERROR(AVERAGEIFS(RawData!$H:$H,RawData!$A:$A,설정!$C$4,RawData!$B:$B,$A12,RawData!$C:$C,$B12,RawData!$D:$D,$D12),0) -> 11575 | I12: =SUM(F12:H12) -> 38991.667 | J12: =IF($I12=0,0,F12/$I12) -> 0.60739474 | K12: =IF($I12=0,0,G12/$I12) -> 0.095746954 | L12: =IF($I12=0,0,H12/$I12) -> 0.2968583
A13: =설정!$C$5 -> 2025 | B13: =설정!$C$8 -> FW | C13: =A13&" "&B13 -> 2025 FW | D13: =설정!$C$11 -> 셔츠 | E13: =COUNTIFS(RawData!$A:$A,설정!$C$4,RawData!$B:$B,$A13,RawData!$C:$C,$B13,RawData!$D:$D,$D13) -> 9 | F13: =IFERROR(AVERAGEIFS(RawData!$F:$F,RawData!$A:$A,설정!$C$4,RawData!$B:$B,$A13,RawData!$C:$C,$B13,RawData!$D:$D,$D13),0) -> 13011.111 | G13: =IFERROR(AVERAGEIFS(RawData!$G:$G,RawData!$A:$A,설정!$C$4,RawData!$B:$B,$A13,RawData!$C:$C,$B13,RawData!$D:$D,$D13),0) -> 2977.7778 | H13: =IFERROR(AVERAGEIFS(RawData!$H:$H,RawData!$A:$A,설정!$C$4,RawData!$B:$B,$A13,RawData!$C:$C,$B13,RawData!$D:$D,$D13),0) -> 7966.6667 | I13: =SUM(F13:H13) -> 23955.556 | J13: =IF($I13=0,0,F13/$I13) -> 0.54313544 | K13: =IF($I13=0,0,G13/$I13) -> 0.12430427 | L13: =IF($I13=0,0,H13/$I13) -> 0.3325603
A14: =설정!$C$5 -> 2025 | B14: =설정!$C$8 -> FW | C14: =A14&" "&B14 -> 2025 FW | D14: =설정!$C$12 -> 팬츠 | E14: =COUNTIFS(RawData!$A:$A,설정!$C$4,RawData!$B:$B,$A14,RawData!$C:$C,$B14,RawData!$D:$D,$D14) -> 10 | F14: =IFERROR(AVERAGEIFS(RawData!$F:$F,RawData!$A:$A,설정!$C$4,RawData!$B:$B,$A14,RawData!$C:$C,$B14,RawData!$D:$D,$D14),0) -> 16110 | G14: =IFERROR(AVERAGEIFS(RawData!$G:$G,RawData!$A:$A,설정!$C$4,RawData!$B:$B,$A14,RawData!$C:$C,$B14,RawData!$D:$D,$D14),0) -> 4120 | H14: =IFERROR(AVERAGEIFS(RawData!$H:$H,RawData!$A:$A,설정!$C$4,RawData!$B:$B,$A14,RawData!$C:$C,$B14,RawData!$D:$D,$D14),0) -> 9230 | I14: =SUM(F14:H14) -> 29460 | J14: =IF($I14=0,0,F14/$I14) -> 0.54684318 | K14: =IF($I14=0,0,G14/$I14) -> 0.13985064 | L14: =IF($I14=0,0,H14/$I14) -> 0.31330618
A15: =설정!$C$5 -> 2025 | B15: =설정!$C$8 -> FW | C15: =A15&" "&B15 -> 2025 FW | D15: =설정!$C$13 -> 스커트 | E15: =COUNTIFS(RawData!$A:$A,설정!$C$4,RawData!$B:$B,$A15,RawData!$C:$C,$B15,RawData!$D:$D,$D15) -> 8 | F15: =IFERROR(AVERAGEIFS(RawData!$F:$F,RawData!$A:$A,설정!$C$4,RawData!$B:$B,$A15,RawData!$C:$C,$B15,RawData!$D:$D,$D15),0) -> 14037.5 | G15: =IFERROR(AVERAGEIFS(RawData!$G:$G,RawData!$A:$A,설정!$C$4,RawData!$B:$B,$A15,RawData!$C:$C,$B15,RawData!$D:$D,$D15),0) -> 3212.5 | H15: =IFERROR(AVERAGEIFS(RawData!$H:$H,RawData!$A:$A,설정!$C$4,RawData!$B:$B,$A15,RawData!$C:$C,$B15,RawData!$D:$D,$D15),0) -> 8450 | I15: =SUM(F15:H15) -> 25700 | J15: =IF($I15=0,0,F15/$I15) -> 0.54620623 | K15: =IF($I15=0,0,G15/$I15) -> 0.125 | L15: =IF($I15=0,0,H15/$I15) -> 0.32879377
A16: =설정!$C$5 -> 2025 | B16: =설정!$C$8 -> FW | C16: =A16&" "&B16 -> 2025 FW | D16: =설정!$C$14 -> 원피스 | E16: =COUNTIFS(RawData!$A:$A,설정!$C$4,RawData!$B:$B,$A16,RawData!$C:$C,$B16,RawData!$D:$D,$D16) -> 12 | F16: =IFERROR(AVERAGEIFS(RawData!$F:$F,RawData!$A:$A,설정!$C$4,RawData!$B:$B,$A16,RawData!$C:$C,$B16,RawData!$D:$D,$D16),0) -> 21408.333 | G16: =IFERROR(AVERAGEIFS(RawData!$G:$G,RawData!$A:$A,설정!$C$4,RawData!$B:$B,$A16,RawData!$C:$C,$B16,RawData!$D:$D,$D16),0) -> 4233.3333 | H16: =IFERROR(AVERAGEIFS(RawData!$H:$H,RawData!$A:$A,설정!$C$4,RawData!$B:$B,$A16,RawData!$C:$C,$B16,RawData!$D:$D,$D16),0) -> 12758.333 | I16: =SUM(F16:H16) -> 38400 | J16: =IF($I16=0,0,F16/$I16) -> 0.55750868 | K16: =IF($I16=0,0,G16/$I16) -> 0.11024306 | L16: =IF($I16=0,0,H16/$I16) -> 0.33224826
A17: =설정!$C$6 -> 2026 | B17: =설정!$C$7 -> SS | C17: =A17&" "&B17 -> 2026 SS | D17: =설정!$C$9 -> 아우터 | E17: =COUNTIFS(RawData!$A:$A,설정!$C$4,RawData!$B:$B,$A17,RawData!$C:$C,$B17,RawData!$D:$D,$D17) -> 12 | F17: =IFERROR(AVERAGEIFS(RawData!$F:$F,RawData!$A:$A,설정!$C$4,RawData!$B:$B,$A17,RawData!$C:$C,$B17,RawData!$D:$D,$D17),0) -> 46608.333 | G17: =IFERROR(AVERAGEIFS(RawData!$G:$G,RawData!$A:$A,설정!$C$4,RawData!$B:$B,$A17,RawData!$C:$C,$B17,RawData!$D:$D,$D17),0) -> 7625 | H17: =IFERROR(AVERAGEIFS(RawData!$H:$H,RawData!$A:$A,설정!$C$4,RawData!$B:$B,$A17,RawData!$C:$C,$B17,RawData!$D:$D,$D17),0) -> 29891.667 | I17: =SUM(F17:H17) -> 84125 | J17: =IF($I17=0,0,F17/$I17) -> 0.55403665 | K17: =IF($I17=0,0,G17/$I17) -> 0.09063893 | L17: =IF($I17=0,0,H17/$I17) -> 0.35532442
A18: =설정!$C$6 -> 2026 | B18: =설정!$C$7 -> SS | C18: =A18&" "&B18 -> 2026 SS | D18: =설정!$C$10 -> 니트 | E18: =COUNTIFS(RawData!$A:$A,설정!$C$4,RawData!$B:$B,$A18,RawData!$C:$C,$B18,RawData!$D:$D,$D18) -> 10 | F18: =IFERROR(AVERAGEIFS(RawData!$F:$F,RawData!$A:$A,설정!$C$4,RawData!$B:$B,$A18,RawData!$C:$C,$B18,RawData!$D:$D,$D18),0) -> 18700 | G18: =IFERROR(AVERAGEIFS(RawData!$G:$G,RawData!$A:$A,설정!$C$4,RawData!$B:$B,$A18,RawData!$C:$C,$B18,RawData!$D:$D,$D18),0) -> 2640 | H18: =IFERROR(AVERAGEIFS(RawData!$H:$H,RawData!$A:$A,설정!$C$4,RawData!$B:$B,$A18,RawData!$C:$C,$B18,RawData!$D:$D,$D18),0) -> 12130 | I18: =SUM(F18:H18) -> 33470 | J18: =IF($I18=0,0,F18/$I18) -> 0.55870929 | K18: =IF($I18=0,0,G18/$I18) -> 0.078876606 | L18: =IF($I18=0,0,H18/$I18) -> 0.3624141
A19: =설정!$C$6 -> 2026 | B19: =설정!$C$7 -> SS | C19: =A19&" "&B19 -> 2026 SS | D19: =설정!$C$11 -> 셔츠 | E19: =COUNTIFS(RawData!$A:$A,설정!$C$4,RawData!$B:$B,$A19,RawData!$C:$C,$B19,RawData!$D:$D,$D19) -> 12 | F19: =IFERROR(AVERAGEIFS(RawData!$F:$F,RawData!$A:$A,설정!$C$4,RawData!$B:$B,$A19,RawData!$C:$C,$B19,RawData!$D:$D,$D19),0) -> 10241.667 | G19: =IFERROR(AVERAGEIFS(RawData!$G:$G,RawData!$A:$A,설정!$C$4,RawData!$B:$B,$A19,RawData!$C:$C,$B19,RawData!$D:$D,$D19),0) -> 2158.3333 | H19: =IFERROR(AVERAGEIFS(RawData!$H:$H,RawData!$A:$A,설정!$C$4,RawData!$B:$B,$A19,RawData!$C:$C,$B19,RawData!$D:$D,$D19),0) -> 8833.3333 | I19: =SUM(F19:H19) -> 21233.333 | J19: =IF($I19=0,0,F19/$I19) -> 0.48233909 | K19: =IF($I19=0,0,G19/$I19) -> 0.10164835 | L19: =IF($I19=0,0,H19/$I19) -> 0.41601256
A20: =설정!$C$6 -> 2026 | B20: =설정!$C$7 -> SS | C20: =A20&" "&B20 -> 2026 SS | D20: =설정!$C$12 -> 팬츠 | E20: =COUNTIFS(RawData!$A:$A,설정!$C$4,RawData!$B:$B,$A20,RawData!$C:$C,$B20,RawData!$D:$D,$D20) -> 10 | F20: =IFERROR(AVERAGEIFS(RawData!$F:$F,RawData!$A:$A,설정!$C$4,RawData!$B:$B,$A20,RawData!$C:$C,$B20,RawData!$D:$D,$D20),0) -> 12870 | G20: =IFERROR(AVERAGEIFS(RawData!$G:$G,RawData!$A:$A,설정!$C$4,RawData!$B:$B,$A20,RawData!$C:$C,$B20,RawData!$D:$D,$D20),0) -> 3170 | H20: =IFERROR(AVERAGEIFS(RawData!$H:$H,RawData!$A:$A,설정!$C$4,RawData!$B:$B,$A20,RawData!$C:$C,$B20,RawData!$D:$D,$D20),0) -> 9890 | I20: =SUM(F20:H20) -> 25930 | J20: =IF($I20=0,0,F20/$I20) -> 0.49633629 | K20: =IF($I20=0,0,G20/$I20) -> 0.12225222 | L20: =IF($I20=0,0,H20/$I20) -> 0.38141149
A21: =설정!$C$6 -> 2026 | B21: =설정!$C$7 -> SS | C21: =A21&" "&B21 -> 2026 SS | D21: =설정!$C$13 -> 스커트 | E21: =COUNTIFS(RawData!$A:$A,설정!$C$4,RawData!$B:$B,$A21,RawData!$C:$C,$B21,RawData!$D:$D,$D21) -> 12 | F21: =IFERROR(AVERAGEIFS(RawData!$F:$F,RawData!$A:$A,설정!$C$4,RawData!$B:$B,$A21,RawData!$C:$C,$B21,RawData!$D:$D,$D21),0) -> 10275 | G21: =IFERROR(AVERAGEIFS(RawData!$G:$G,RawData!$A:$A,설정!$C$4,RawData!$B:$B,$A21,RawData!$C:$C,$B21,RawData!$D:$D,$D21),0) -> 2708.3333 | H21: =IFERROR(AVERAGEIFS(RawData!$H:$H,RawData!$A:$A,설정!$C$4,RawData!$B:$B,$A21,RawData!$C:$C,$B21,RawData!$D:$D,$D21),0) -> 9258.3333 | I21: =SUM(F21:H21) -> 22241.667 | J21: =IF($I21=0,0,F21/$I21) -> 0.46197078 | K21: =IF($I21=0,0,G21/$I21) -> 0.12176845 | L21: =IF($I21=0,0,H21/$I21) -> 0.41626077
A22: =설정!$C$6 -> 2026 | B22: =설정!$C$7 -> SS | C22: =A22&" "&B22 -> 2026 SS | D22: =설정!$C$14 -> 원피스 | E22: =COUNTIFS(RawData!$A:$A,설정!$C$4,RawData!$B:$B,$A22,RawData!$C:$C,$B22,RawData!$D:$D,$D22) -> 8 | F22: =IFERROR(AVERAGEIFS(RawData!$F:$F,RawData!$A:$A,설정!$C$4,RawData!$B:$B,$A22,RawData!$C:$C,$B22,RawData!$D:$D,$D22),0) -> 17150 | G22: =IFERROR(AVERAGEIFS(RawData!$G:$G,RawData!$A:$A,설정!$C$4,RawData!$B:$B,$A22,RawData!$C:$C,$B22,RawData!$D:$D,$D22),0) -> 3412.5 | H22: =IFERROR(AVERAGEIFS(RawData!$H:$H,RawData!$A:$A,설정!$C$4,RawData!$B:$B,$A22,RawData!$C:$C,$B22,RawData!$D:$D,$D22),0) -> 13475 | I22: =SUM(F22:H22) -> 34037.5 | J22: =IF($I22=0,0,F22/$I22) -> 0.50385604 | K22: =IF($I22=0,0,G22/$I22) -> 0.10025707 | L22: =IF($I22=0,0,H22/$I22) -> 0.39588689
A23: =설정!$C$6 -> 2026 | B23: =설정!$C$8 -> FW | C23: =A23&" "&B23 -> 2026 FW | D23: =설정!$C$9 -> 아우터 | E23: =COUNTIFS(RawData!$A:$A,설정!$C$4,RawData!$B:$B,$A23,RawData!$C:$C,$B23,RawData!$D:$D,$D23) -> 11 | F23: =IFERROR(AVERAGEIFS(RawData!$F:$F,RawData!$A:$A,설정!$C$4,RawData!$B:$B,$A23,RawData!$C:$C,$B23,RawData!$D:$D,$D23),0) -> 62854.545 | G23: =IFERROR(AVERAGEIFS(RawData!$G:$G,RawData!$A:$A,설정!$C$4,RawData!$B:$B,$A23,RawData!$C:$C,$B23,RawData!$D:$D,$D23),0) -> 10690.909 | H23: =IFERROR(AVERAGEIFS(RawData!$H:$H,RawData!$A:$A,설정!$C$4,RawData!$B:$B,$A23,RawData!$C:$C,$B23,RawData!$D:$D,$D23),0) -> 30563.636 | I23: =SUM(F23:H23) -> 104109.09 | J23: =IF($I23=0,0,F23/$I23) -> 0.60373734 | K23: =IF($I23=0,0,G23/$I23) -> 0.10268949 | L23: =IF($I23=0,0,H23/$I23) -> 0.29357317
A24: =설정!$C$6 -> 2026 | B24: =설정!$C$8 -> FW | C24: =A24&" "&B24 -> 2026 FW | D24: =설정!$C$10 -> 니트 | E24: =COUNTIFS(RawData!$A:$A,설정!$C$4,RawData!$B:$B,$A24,RawData!$C:$C,$B24,RawData!$D:$D,$D24) -> 9 | F24: =IFERROR(AVERAGEIFS(RawData!$F:$F,RawData!$A:$A,설정!$C$4,RawData!$B:$B,$A24,RawData!$C:$C,$B24,RawData!$D:$D,$D24),0) -> 24177.778 | G24: =IFERROR(AVERAGEIFS(RawData!$G:$G,RawData!$A:$A,설정!$C$4,RawData!$B:$B,$A24,RawData!$C:$C,$B24,RawData!$D:$D,$D24),0) -> 3666.6667 | H24: =IFERROR(AVERAGEIFS(RawData!$H:$H,RawData!$A:$A,설정!$C$4,RawData!$B:$B,$A24,RawData!$C:$C,$B24,RawData!$D:$D,$D24),0) -> 13000 | I24: =SUM(F24:H24) -> 40844.444 | J24: =IF($I24=0,0,F24/$I24) -> 0.59194777 | K24: =IF($I24=0,0,G24/$I24) -> 0.089771491 | L24: =IF($I24=0,0,H24/$I24) -> 0.31828074
A25: =설정!$C$6 -> 2026 | B25: =설정!$C$8 -> FW | C25: =A25&" "&B25 -> 2026 FW | D25: =설정!$C$11 -> 셔츠 | E25: =COUNTIFS(RawData!$A:$A,설정!$C$4,RawData!$B:$B,$A25,RawData!$C:$C,$B25,RawData!$D:$D,$D25) -> 8 | F25: =IFERROR(AVERAGEIFS(RawData!$F:$F,RawData!$A:$A,설정!$C$4,RawData!$B:$B,$A25,RawData!$C:$C,$B25,RawData!$D:$D,$D25),0) -> 13450 | G25: =IFERROR(AVERAGEIFS(RawData!$G:$G,RawData!$A:$A,설정!$C$4,RawData!$B:$B,$A25,RawData!$C:$C,$B25,RawData!$D:$D,$D25),0) -> 3200 | H25: =IFERROR(AVERAGEIFS(RawData!$H:$H,RawData!$A:$A,설정!$C$4,RawData!$B:$B,$A25,RawData!$C:$C,$B25,RawData!$D:$D,$D25),0) -> 8662.5 | I25: =SUM(F25:H25) -> 25312.5 | J25: =IF($I25=0,0,F25/$I25) -> 0.53135802 | K25: =IF($I25=0,0,G25/$I25) -> 0.12641975 | L25: =IF($I25=0,0,H25/$I25) -> 0.34222222
A26: =설정!$C$6 -> 2026 | B26: =설정!$C$8 -> FW | C26: =A26&" "&B26 -> 2026 FW | D26: =설정!$C$12 -> 팬츠 | E26: =COUNTIFS(RawData!$A:$A,설정!$C$4,RawData!$B:$B,$A26,RawData!$C:$C,$B26,RawData!$D:$D,$D26) -> 9 | F26: =IFERROR(AVERAGEIFS(RawData!$F:$F,RawData!$A:$A,설정!$C$4,RawData!$B:$B,$A26,RawData!$C:$C,$B26,RawData!$D:$D,$D26),0) -> 16700 | G26: =IFERROR(AVERAGEIFS(RawData!$G:$G,RawData!$A:$A,설정!$C$4,RawData!$B:$B,$A26,RawData!$C:$C,$B26,RawData!$D:$D,$D26),0) -> 4244.4444 | H26: =IFERROR(AVERAGEIFS(RawData!$H:$H,RawData!$A:$A,설정!$C$4,RawData!$B:$B,$A26,RawData!$C:$C,$B26,RawData!$D:$D,$D26),0) -> 9933.3333 | I26: =SUM(F26:H26) -> 30877.778 | J26: =IF($I26=0,0,F26/$I26) -> 0.54084203 | K26: =IF($I26=0,0,G26/$I26) -> 0.13745952 | L26: =IF($I26=0,0,H26/$I26) -> 0.32169845
A27: =설정!$C$6 -> 2026 | B27: =설정!$C$8 -> FW | C27: =A27&" "&B27 -> 2026 FW | D27: =설정!$C$13 -> 스커트 | E27: =COUNTIFS(RawData!$A:$A,설정!$C$4,RawData!$B:$B,$A27,RawData!$C:$C,$B27,RawData!$D:$D,$D27) -> 8 | F27: =IFERROR(AVERAGEIFS(RawData!$F:$F,RawData!$A:$A,설정!$C$4,RawData!$B:$B,$A27,RawData!$C:$C,$B27,RawData!$D:$D,$D27),0) -> 13512.5 | G27: =IFERROR(AVERAGEIFS(RawData!$G:$G,RawData!$A:$A,설정!$C$4,RawData!$B:$B,$A27,RawData!$C:$C,$B27,RawData!$D:$D,$D27),0) -> 3625 | H27: =IFERROR(AVERAGEIFS(RawData!$H:$H,RawData!$A:$A,설정!$C$4,RawData!$B:$B,$A27,RawData!$C:$C,$B27,RawData!$D:$D,$D27),0) -> 8925 | I27: =SUM(F27:H27) -> 26062.5 | J27: =IF($I27=0,0,F27/$I27) -> 0.51846523 | K27: =IF($I27=0,0,G27/$I27) -> 0.13908873 | L27: =IF($I27=0,0,H27/$I27) -> 0.34244604
A28: =설정!$C$6 -> 2026 | B28: =설정!$C$8 -> FW | C28: =A28&" "&B28 -> 2026 FW | D28: =설정!$C$14 -> 원피스 | E28: =COUNTIFS(RawData!$A:$A,설정!$C$4,RawData!$B:$B,$A28,RawData!$C:$C,$B28,RawData!$D:$D,$D28) -> 12 | F28: =IFERROR(AVERAGEIFS(RawData!$F:$F,RawData!$A:$A,설정!$C$4,RawData!$B:$B,$A28,RawData!$C:$C,$B28,RawData!$D:$D,$D28),0) -> 22116.667 | G28: =IFERROR(AVERAGEIFS(RawData!$G:$G,RawData!$A:$A,설정!$C$4,RawData!$B:$B,$A28,RawData!$C:$C,$B28,RawData!$D:$D,$D28),0) -> 4766.6667 | H28: =IFERROR(AVERAGEIFS(RawData!$H:$H,RawData!$A:$A,설정!$C$4,RawData!$B:$B,$A28,RawData!$C:$C,$B28,RawData!$D:$D,$D28),0) -> 13458.333 | I28: =SUM(F28:H28) -> 40341.667 | J28: =IF($I28=0,0,F28/$I28) -> 0.54823384 | K28: =IF($I28=0,0,G28/$I28) -> 0.11815741 | L28: =IF($I28=0,0,H28/$I28) -> 0.33360876

Sheet 차트데이터
A1: 차트용 집계표 (자동 계산 — 수정 불필요)
A3: 원자재 평균
A4: 품목 | B4: =설정!$C$5&" "&설정!$C$7 -> 2025 SS | C4: =설정!$C$5&" "&설정!$C$8 -> 2025 FW | D4: =설정!$C$6&" "&설정!$C$7 -> 2026 SS | E4: =설정!$C$6&" "&설정!$C$8 -> 2026 FW | F4: SS 전년대비 | G4: FW 전년대비
A5: =설정!$C$9 -> 아우터 | B5: =IFERROR(AVERAGEIFS(RawData!$F:$F,RawData!$A:$A,설정!$C$4,RawData!$B:$B,설정!$C$5,RawData!$C:$C,설정!$C$7,RawData!$D:$D,설정!$C$9),0) -> 46230 | C5: =IFERROR(AVERAGEIFS(RawData!$F:$F,RawData!$A:$A,설정!$C$4,RawData!$B:$B,설정!$C$5,RawData!$C:$C,설정!$C$8,RawData!$D:$D,설정!$C$9),0) -> 57677.778 | D5: =IFERROR(AVERAGEIFS(RawData!$F:$F,RawData!$A:$A,설정!$C$4,RawData!$B:$B,설정!$C$6,RawData!$C:$C,설정!$C$7,RawData!$D:$D,설정!$C$9),0) -> 46608.333 | E5: =IFERROR(AVERAGEIFS(RawData!$F:$F,RawData!$A:$A,설정!$C$4,RawData!$B:$B,설정!$C$6,RawData!$C:$C,설정!$C$8,RawData!$D:$D,설정!$C$9),0) -> 62854.545 | F5: =IF(B5=0,0,D5/B5-1) -> 0.0081837191 | G5: =IF(C5=0,0,E5/C5-1) -> 0.089753244
A6: =설정!$C$10 -> 니트 | B6: =IFERROR(AVERAGEIFS(RawData!$F:$F,RawData!$A:$A,설정!$C$4,RawData!$B:$B,설정!$C$5,RawData!$C:$C,설정!$C$7,RawData!$D:$D,설정!$C$10),0) -> 17233.333 | C6: =IFERROR(AVERAGEIFS(RawData!$F:$F,RawData!$A:$A,설정!$C$4,RawData!$B:$B,설정!$C$5,RawData!$C:$C,설정!$C$8,RawData!$D:$D,설정!$C$10),0) -> 23683.333 | D6: =IFERROR(AVERAGEIFS(RawData!$F:$F,RawData!$A:$A,설정!$C$4,RawData!$B:$B,설정!$C$6,RawData!$C:$C,설정!$C$7,RawData!$D:$D,설정!$C$10),0) -> 18700 | E6: =IFERROR(AVERAGEIFS(RawData!$F:$F,RawData!$A:$A,설정!$C$4,RawData!$B:$B,설정!$C$6,RawData!$C:$C,설정!$C$8,RawData!$D:$D,설정!$C$10),0) -> 24177.778 | F6: =IF(B6=0,0,D6/B6-1) -> 0.085106383 | G6: =IF(C6=0,0,E6/C6-1) -> 0.020877316
A7: =설정!$C$11 -> 셔츠 | B7: =IFERROR(AVERAGEIFS(RawData!$F:$F,RawData!$A:$A,설정!$C$4,RawData!$B:$B,설정!$C$5,RawData!$C:$C,설정!$C$7,RawData!$D:$D,설정!$C$11),0) -> 9666.6667 | C7: =IFERROR(AVERAGEIFS(RawData!$F:$F,RawData!$A:$A,설정!$C$4,RawData!$B:$B,설정!$C$5,RawData!$C:$C,설정!$C$8,RawData!$D:$D,설정!$C$11),0) -> 13011.111 | D7: =IFERROR(AVERAGEIFS(RawData!$F:$F,RawData!$A:$A,설정!$C$4,RawData!$B:$B,설정!$C$6,RawData!$C:$C,설정!$C$7,RawData!$D:$D,설정!$C$11),0) -> 10241.667 | E7: =IFERROR(AVERAGEIFS(RawData!$F:$F,RawData!$A:$A,설정!$C$4,RawData!$B:$B,설정!$C$6,RawData!$C:$C,설정!$C$8,RawData!$D:$D,설정!$C$11),0) -> 13450 | F7: =IF(B7=0,0,D7/B7-1) -> 0.059482759 | G7: =IF(C7=0,0,E7/C7-1) -> 0.033731853
A8: =설정!$C$12 -> 팬츠 | B8: =IFERROR(AVERAGEIFS(RawData!$F:$F,RawData!$A:$A,설정!$C$4,RawData!$B:$B,설정!$C$5,RawData!$C:$C,설정!$C$7,RawData!$D:$D,설정!$C$12),0) -> 12236.364 | C8: =IFERROR(AVERAGEIFS(RawData!$F:$F,RawData!$A:$A,설정!$C$4,RawData!$B:$B,설정!$C$5,RawData!$C:$C,설정!$C$8,RawData!$D:$D,설정!$C$12),0) -> 16110 | D8: =IFERROR(AVERAGEIFS(RawData!$F:$F,RawData!$A:$A,설정!$C$4,RawData!$B:$B,설정!$C$6,RawData!$C:$C,설정!$C$7,RawData!$D:$D,설정!$C$12),0) -> 12870 | E8: =IFERROR(AVERAGEIFS(RawData!$F:$F,RawData!$A:$A,설정!$C$4,RawData!$B:$B,설정!$C$6,RawData!$C:$C,설정!$C$8,RawData!$D:$D,설정!$C$12),0) -> 16700 | F8: =IF(B8=0,0,D8/B8-1) -> 0.051783061 | G8: =IF(C8=0,0,E8/C8-1) -> 0.036623215
A9: =설정!$C$13 -> 스커트 | B9: =IFERROR(AVERAGEIFS(RawData!$F:$F,RawData!$A:$A,설정!$C$4,RawData!$B:$B,설정!$C$5,RawData!$C:$C,설정!$C$7,RawData!$D:$D,설정!$C$13),0) -> 10050 | C9: =IFERROR(AVERAGEIFS(RawData!$F:$F,RawData!$A:$A,설정!$C$4,RawData!$B:$B,설정!$C$5,RawData!$C:$C,설정!$C$8,RawData!$D:$D,설정!$C$13),0) -> 14037.5 | D9: =IFERROR(AVERAGEIFS(RawData!$F:$F,RawData!$A:$A,설정!$C$4,RawData!$B:$B,설정!$C$6,RawData!$C:$C,설정!$C$7,RawData!$D:$D,설정!$C$13),0) -> 10275 | E9: =IFERROR(AVERAGEIFS(RawData!$F:$F,RawData!$A:$A,설정!$C$4,RawData!$B:$B,설정!$C$6,RawData!$C:$C,설정!$C$8,RawData!$D:$D,설정!$C$13),0) -> 13512.5 | F9: =IF(B9=0,0,D9/B9-1) -> 0.02238806 | G9: =IF(C9=0,0,E9/C9-1) -> -0.037399822
A10: =설정!$C$14 -> 원피스 | B10: =IFERROR(AVERAGEIFS(RawData!$F:$F,RawData!$A:$A,설정!$C$4,RawData!$B:$B,설정!$C$5,RawData!$C:$C,설정!$C$7,RawData!$D:$D,설정!$C$14),0) -> 15755.556 | C10: =IFERROR(AVERAGEIFS(RawData!$F:$F,RawData!$A:$A,설정!$C$4,RawData!$B:$B,설정!$C$5,RawData!$C:$C,설정!$C$8,RawData!$D:$D,설정!$C$14),0) -> 21408.333 | D10: =IFERROR(AVERAGEIFS(RawData!$F:$F,RawData!$A:$A,설정!$C$4,RawData!$B:$B,설정!$C$6,RawData!$C:$C,설정!$C$7,RawData!$D:$D,설정!$C$14),0) -> 17150 | E10: =IFERROR(AVERAGEIFS(RawData!$F:$F,RawData!$A:$A,설정!$C$4,RawData!$B:$B,설정!$C$6,RawData!$C:$C,설정!$C$8,RawData!$D:$D,설정!$C$14),0) -> 22116.667 | F10: =IF(B10=0,0,D10/B10-1) -> 0.088504937 | G10: =IF(C10=0,0,E10/C10-1) -> 0.033086804
A12: 부자재 평균
A13: 품목 | B13: =설정!$C$5&" "&설정!$C$7 -> 2025 SS | C13: =설정!$C$5&" "&설정!$C$8 -> 2025 FW | D13: =설정!$C$6&" "&설정!$C$7 -> 2026 SS | E13: =설정!$C$6&" "&설정!$C$8 -> 2026 FW | F13: SS 전년대비 | G13: FW 전년대비
A14: =설정!$C$9 -> 아우터 | B14: =IFERROR(AVERAGEIFS(RawData!$G:$G,RawData!$A:$A,설정!$C$4,RawData!$B:$B,설정!$C$5,RawData!$C:$C,설정!$C$7,RawData!$D:$D,설정!$C$9),0) -> 6860 | C14: =IFERROR(AVERAGEIFS(RawData!$G:$G,RawData!$A:$A,설정!$C$4,RawData!$B:$B,설정!$C$5,RawData!$C:$C,설정!$C$8,RawData!$D:$D,설정!$C$9),0) -> 11811.111 | D14: =IFERROR(AVERAGEIFS(RawData!$G:$G,RawData!$A:$A,설정!$C$4,RawData!$B:$B,설정!$C$6,RawData!$C:$C,설정!$C$7,RawData!$D:$D,설정!$C$9),0) -> 7625 | E14: =IFERROR(AVERAGEIFS(RawData!$G:$G,RawData!$A:$A,설정!$C$4,RawData!$B:$B,설정!$C$6,RawData!$C:$C,설정!$C$8,RawData!$D:$D,설정!$C$9),0) -> 10690.909 | F14: =IF(B14=0,0,D14/B14-1) -> 0.11151603 | G14: =IF(C14=0,0,E14/C14-1) -> -0.094843069
A15: =설정!$C$10 -> 니트 | B15: =IFERROR(AVERAGEIFS(RawData!$G:$G,RawData!$A:$A,설정!$C$4,RawData!$B:$B,설정!$C$5,RawData!$C:$C,설정!$C$7,RawData!$D:$D,설정!$C$10),0) -> 2522.2222 | C15: =IFERROR(AVERAGEIFS(RawData!$G:$G,RawData!$A:$A,설정!$C$4,RawData!$B:$B,설정!$C$5,RawData!$C:$C,설정!$C$8,RawData!$D:$D,설정!$C$10),0) -> 3733.3333 | D15: =IFERROR(AVERAGEIFS(RawData!$G:$G,RawData!$A:$A,설정!$C$4,RawData!$B:$B,설정!$C$6,RawData!$C:$C,설정!$C$7,RawData!$D:$D,설정!$C$10),0) -> 2640 | E15: =IFERROR(AVERAGEIFS(RawData!$G:$G,RawData!$A:$A,설정!$C$4,RawData!$B:$B,설정!$C$6,RawData!$C:$C,설정!$C$8,RawData!$D:$D,설정!$C$10),0) -> 3666.6667 | F15: =IF(B15=0,0,D15/B15-1) -> 0.046696035 | G15: =IF(C15=0,0,E15/C15-1) -> -0.017857143
A16: =설정!$C$11 -> 셔츠 | B16: =IFERROR(AVERAGEIFS(RawData!$G:$G,RawData!$A:$A,설정!$C$4,RawData!$B:$B,설정!$C$5,RawData!$C:$C,설정!$C$7,RawData!$D:$D,설정!$C$11),0) -> 2158.3333 | C16: =IFERROR(AVERAGEIFS(RawData!$G:$G,RawData!$A:$A,설정!$C$4,RawData!$B:$B,설정!$C$5,RawData!$C:$C,설정!$C$8,RawData!$D:$D,설정!$C$11),0) -> 2977.7778 | D16: =IFERROR(AVERAGEIFS(RawData!$G:$G,RawData!$A:$A,설정!$C$4,RawData!$B:$B,설정!$C$6,RawData!$C:$C,설정!$C$7,RawData!$D:$D,설정!$C$11),0) -> 2158.3333 | E16: =IFERROR(AVERAGEIFS(RawData!$G:$G,RawData!$A:$A,설정!$C$4,RawData!$B:$B,설정!$C$6,RawData!$C:$C,설정!$C$8,RawData!$D:$D,설정!$C$11),0) -> 3200 | F16: =IF(B16=0,0,D16/B16-1) -> 0 | G16: =IF(C16=0,0,E16/C16-1) -> 0.074626866
A17: =설정!$C$12 -> 팬츠 | B17: =IFERROR(AVERAGEIFS(RawData!$G:$G,RawData!$A:$A,설정!$C$4,RawData!$B:$B,설정!$C$5,RawData!$C:$C,설정!$C$7,RawData!$D:$D,설정!$C$12),0) -> 2954.5455 | C17: =IFERROR(AVERAGEIFS(RawData!$G:$G,RawData!$A:$A,설정!$C$4,RawData!$B:$B,설정!$C$5,RawData!$C:$C,설정!$C$8,RawData!$D:$D,설정!$C$12),0) -> 4120 | D17: =IFERROR(AVERAGEIFS(RawData!$G:$G,RawData!$A:$A,설정!$C$4,RawData!$B:$B,설정!$C$6,RawData!$C:$C,설정!$C$7,RawData!$D:$D,설정!$C$12),0) -> 3170 | E17: =IFERROR(AVERAGEIFS(RawData!$G:$G,RawData!$A:$A,설정!$C$4,RawData!$B:$B,설정!$C$6,RawData!$C:$C,설정!$C$8,RawData!$D:$D,설정!$C$12),0) -> 4244.4444 | F17: =IF(B17=0,0,D17/B17-1) -> 0.072923077 | G17: =IF(C17=0,0,E17/C17-1) -> 0.030204962
A18: =설정!$C$13 -> 스커트 | B18: =IFERROR(AVERAGEIFS(RawData!$G:$G,RawData!$A:$A,설정!$C$4,RawData!$B:$B,설정!$C$5,RawData!$C:$C,설정!$C$7,RawData!$D:$D,설정!$C$13),0) -> 2433.3333 | C18: =IFERROR(AVERAGEIFS(RawData!$G:$G,RawData!$A:$A,설정!$C$4,RawData!$B:$B,설정!$C$5,RawData!$C:$C,설정!$C$8,RawData!$D:$D,설정!$C$13),0) -> 3212.5 | D18: =IFERROR(AVERAGEIFS(RawData!$G:$G,RawData!$A:$A,설정!$C$4,RawData!$B:$B,설정!$C$6,RawData!$C:$C,설정!$C$7,RawData!$D:$D,설정!$C$13),0) -> 2708.3333 | E18: =IFERROR(AVERAGEIFS(RawData!$G:$G,RawData!$A:$A,설정!$C$4,RawData!$B:$B,설정!$C$6,RawData!$C:$C,설정!$C$8,RawData!$D:$D,설정!$C$13),0) -> 3625 | F18: =IF(B18=0,0,D18/B18-1) -> 0.1130137 | G18: =IF(C18=0,0,E18/C18-1) -> 0.12840467
A19: =설정!$C$14 -> 원피스 | B19: =IFERROR(AVERAGEIFS(RawData!$G:$G,RawData!$A:$A,설정!$C$4,RawData!$B:$B,설정!$C$5,RawData!$C:$C,설정!$C$7,RawData!$D:$D,설정!$C$14),0) -> 3400 | C19: =IFERROR(AVERAGEIFS(RawData!$G:$G,RawData!$A:$A,설정!$C$4,RawData!$B:$B,설정!$C$5,RawData!$C:$C,설정!$C$8,RawData!$D:$D,설정!$C$14),0) -> 4233.3333 | D19: =IFERROR(AVERAGEIFS(RawData!$G:$G,RawData!$A:$A,설정!$C$4,RawData!$B:$B,설정!$C$6,RawData!$C:$C,설정!$C$7,RawData!$D:$D,설정!$C$14),0) -> 3412.5 | E19: =IFERROR(AVERAGEIFS(RawData!$G:$G,RawData!$A:$A,설정!$C$4,RawData!$B:$B,설정!$C$6,RawData!$C:$C,설정!$C$8,RawData!$D:$D,설정!$C$14),0) -> 4766.6667 | F19: =IF(B19=0,0,D19/B19-1) -> 0.0036764706 | G19: =IF(C19=0,0,E19/C19-1) -> 0.12598425
A21: 가공임 평균
A22: 품목 | B22: =설정!$C$5&" "&설정!$C$7 -> 2025 SS | C22: =설정!$C$5&" "&설정!$C$8 -> 2025 FW | D22: =설정!$C$6&" "&설정!$C$7 -> 2026 SS | E22: =설정!$C$6&" "&설정!$C$8 -> 2026 FW | F22: SS 전년대비 | G22: FW 전년대비
A23: =설정!$C$9 -> 아우터 | B23: =IFERROR(AVERAGEIFS(RawData!$H:$H,RawData!$A:$A,설정!$C$4,RawData!$B:$B,설정!$C$5,RawData!$C:$C,설정!$C$7,RawData!$D:$D,설정!$C$9),0) -> 27200 | C23: =IFERROR(AVERAGEIFS(RawData!$H:$H,RawData!$A:$A,설정!$C$4,RawData!$B:$B,설정!$C$5,RawData!$C:$C,설정!$C$8,RawData!$D:$D,설정!$C$9),0) -> 26966.667 | D23: =IFERROR(AVERAGEIFS(RawData!$H:$H,RawData!$A:$A,설정!$C$4,RawData!$B:$B,설정!$C$6,RawData!$C:$C,설정!$C$7,RawData!$D:$D,설정!$C$9),0) -> 29891.667 | E23: =IFERROR(AVERAGEIFS(RawData!$H:$H,RawData!$A:$A,설정!$C$4,RawData!$B:$B,설정!$C$6,RawData!$C:$C,설정!$C$8,RawData!$D:$D,설정!$C$9),0) -> 30563.636 | F23: =IF(B23=0,0,D23/B23-1) -> 0.098958333 | G23: =IF(C23=0,0,E23/C23-1) -> 0.13338577
A24: =설정!$C$10 -> 니트 | B24: =IFERROR(AVERAGEIFS(RawData!$H:$H,RawData!$A:$A,설정!$C$4,RawData!$B:$B,설정!$C$5,RawData!$C:$C,설정!$C$7,RawData!$D:$D,설정!$C$10),0) -> 11933.333 | C24: =IFERROR(AVERAGEIFS(RawData!$H:$H,RawData!$A:$A,설정!$C$4,RawData!$B:$B,설정!$C$5,RawData!$C:$C,설정!$C$8,RawData!$D:$D,설정!$C$10),0) -> 11575 | D24: =IFERROR(AVERAGEIFS(RawData!$H:$H,RawData!$A:$A,설정!$C$4,RawData!$B:$B,설정!$C$6,RawData!$C:$C,설정!$C$7,RawData!$D:$D,설정!$C$10),0) -> 12130 | E24: =IFERROR(AVERAGEIFS(RawData!$H:$H,RawData!$A:$A,설정!$C$4,RawData!$B:$B,설정!$C$6,RawData!$C:$C,설정!$C$8,RawData!$D:$D,설정!$C$10),0) -> 13000 | F24: =IF(B24=0,0,D24/B24-1) -> 0.016480447 | G24: =IF(C24=0,0,E24/C24-1) -> 0.12311015
A25: =설정!$C$11 -> 셔츠 | B25: =IFERROR(AVERAGEIFS(RawData!$H:$H,RawData!$A:$A,설정!$C$4,RawData!$B:$B,설정!$C$5,RawData!$C:$C,설정!$C$7,RawData!$D:$D,설정!$C$11),0) -> 7858.3333 | C25: =IFERROR(AVERAGEIFS(RawData!$H:$H,RawData!$A:$A,설정!$C$4,RawData!$B:$B,설정!$C$5,RawData!$C:$C,설정!$C$8,RawData!$D:$D,설정!$C$11),0) -> 7966.6667 | D25: =IFERROR(AVERAGEIFS(RawData!$H:$H,RawData!$A:$A,설정!$C$4,RawData!$B:$B,설정!$C$6,RawData!$C:$C,설정!$C$7,RawData!$D:$D,설정!$C$11),0) -> 8833.3333 | E25: =IFERROR(AVERAGEIFS(RawData!$H:$H,RawData!$A:$A,설정!$C$4,RawData!$B:$B,설정!$C$6,RawData!$C:$C,설정!$C$8,RawData!$D:$D,설정!$C$11),0) -> 8662.5 | F25: =IF(B25=0,0,D25/B25-1) -> 0.12407211 | G25: =IF(C25=0,0,E25/C25-1) -> 0.087343096
A26: =설정!$C$12 -> 팬츠 | B26: =IFERROR(AVERAGEIFS(RawData!$H:$H,RawData!$A:$A,설정!$C$4,RawData!$B:$B,설정!$C$5,RawData!$C:$C,설정!$C$7,RawData!$D:$D,설정!$C$12),0) -> 9272.7273 | C26: =IFERROR(AVERAGEIFS(RawData!$H:$H,RawData!$A:$A,설정!$C$4,RawData!$B:$B,설정!$C$5,RawData!$C:$C,설정!$C$8,RawData!$D:$D,설정!$C$12),0) -> 9230 | D26: =IFERROR(AVERAGEIFS(RawData!$H:$H,RawData!$A:$A,설정!$C$4,RawData!$B:$B,설정!$C$6,RawData!$C:$C,설정!$C$7,RawData!$D:$D,설정!$C$12),0) -> 9890 | E26: =IFERROR(AVERAGEIFS(RawData!$H:$H,RawData!$A:$A,설정!$C$4,RawData!$B:$B,설정!$C$6,RawData!$C:$C,설정!$C$8,RawData!$D:$D,설정!$C$12),0) -> 9933.3333 | F26: =IF(B26=0,0,D26/B26-1) -> 0.066568627 | G26: =IF(C26=0,0,E26/C26-1) -> 0.076200795
A27: =설정!$C$13 -> 스커트 | B27: =IFERROR(AVERAGEIFS(RawData!$H:$H,RawData!$A:$A,설정!$C$4,RawData!$B:$B,설정!$C$5,RawData!$C:$C,설정!$C$7,RawData!$D:$D,설정!$C$13),0) -> 8000 | C27: =IFERROR(AVERAGEIFS(RawData!$H:$H,RawData!$A:$A,설정!$C$4,RawData!$B:$B,설정!$C$5,RawData!$C:$C,설정!$C$8,RawData!$D:$D,설정!$C$13),0) -> 8450 | D27: =IFERROR(AVERAGEIFS(RawData!$H:$H,RawData!$A:$A,설정!$C$4,RawData!$B:$B,설정!$C$6,RawData!$C:$C,설정!$C$7,RawData!$D:$D,설정!$C$13),0) -> 9258.3333 | E27: =IFERROR(AVERAGEIFS(RawData!$H:$H,RawData!$A:$A,설정!$C$4,RawData!$B:$B,설정!$C$6,RawData!$C:$C,설정!$C$8,RawData!$D:$D,설정!$C$13),0) -> 8925 | F27: =IF(B27=0,0,D27/B27-1) -> 0.15729167 | G27: =IF(C27=0,0,E27/C27-1) -> 0.056213018
A28: =설정!$C$14 -> 원피스 | B28: =IFERROR(AVERAGEIFS(RawData!$H:$H,RawData!$A:$A,설정!$C$4,RawData!$B:$B,설정!$C$5,RawData!$C:$C,설정!$C$7,RawData!$D:$D,설정!$C$14),0) -> 13166.667 | C28: =IFERROR(AVERAGEIFS(RawData!$H:$H,RawData!$A:$A,설정!$C$4,RawData!$B:$B,설정!$C$5,RawData!$C:$C,설정!$C$8,RawData!$D:$D,설정!$C$14),0) -> 12758.333 | D28: =IFERROR(AVERAGEIFS(RawData!$H:$H,RawData!$A:$A,설정!$C$4,RawData!$B:$B,설정!$C$6,RawData!$C:$C,설정!$C$7,RawData!$D:$D,설정!$C$14),0) -> 13475 | E28: =IFERROR(AVERAGEIFS(RawData!$H:$H,RawData!$A:$A,설정!$C$4,RawData!$B:$B,설정!$C$6,RawData!$C:$C,설정!$C$8,RawData!$D:$D,설정!$C$14),0) -> 13458.333 | F28: =IF(B28=0,0,D28/B28-1) -> 0.023417722 | G28: =IF(C28=0,0,E28/C28-1) -> 0.054866101
A30: 총원가 평균
A31: 품목 | B31: =설정!$C$5&" "&설정!$C$7 -> 2025 SS | C31: =설정!$C$5&" "&설정!$C$8 -> 2025 FW | D31: =설정!$C$6&" "&설정!$C$7 -> 2026 SS | E31: =설정!$C$6&" "&설정!$C$8 -> 2026 FW | F31: SS 전년대비 | G31: FW 전년대비
A32: =설정!$C$9 -> 아우터 | B32: =B5+B14+B23 -> 80290 | C32: =C5+C14+C23 -> 96455.556 | D32: =D5+D14+D23 -> 84125 | E32: =E5+E14+E23 -> 104109.09 | F32: =IF(B32=0,0,D32/B32-1) -> 0.047764354 | G32: =IF(C32=0,0,E32/C32-1) -> 0.079347792
A33: =설정!$C$10 -> 니트 | B33: =B6+B15+B24 -> 31688.889 | C33: =C6+C15+C24 -> 38991.667 | D33: =D6+D15+D24 -> 33470 | E33: =E6+E15+E24 -> 40844.444 | F33: =IF(B33=0,0,D33/B33-1) -> 0.056206171 | G33: =IF(C33=0,0,E33/C33-1) -> 0.047517276
A34: =설정!$C$11 -> 셔츠 | B34: =B7+B16+B25 -> 19683.333 | C34: =C7+C16+C25 -> 23955.556 | D34: =D7+D16+D25 -> 21233.333 | E34: =E7+E16+E25 -> 25312.5 | F34: =IF(B34=0,0,D34/B34-1) -> 0.078746825 | G34: =IF(C34=0,0,E34/C34-1) -> 0.056644249
A35: =설정!$C$12 -> 팬츠 | B35: =B8+B17+B26 -> 24463.636 | C35: =C8+C17+C26 -> 29460 | D35: =D8+D17+D26 -> 25930 | E35: =E8+E17+E26 -> 30877.778 | F35: =IF(B35=0,0,D35/B35-1) -> 0.059940543 | G35: =IF(C35=0,0,E35/C35-1) -> 0.048125519
A36: =설정!$C$13 -> 스커트 | B36: =B9+B18+B27 -> 20483.333 | C36: =C9+C18+C27 -> 25700 | D36: =D9+D18+D27 -> 22241.667 | E36: =E9+E18+E27 -> 26062.5 | F36: =IF(B36=0,0,D36/B36-1) -> 0.085842148 | G36: =IF(C36=0,0,E36/C36-1) -> 0.014105058
A37: =설정!$C$14 -> 원피스 | B37: =B10+B19+B28 -> 32322.222 | C37: =C10+C19+C28 -> 38400 | D37: =D10+D19+D28 -> 34037.5 | E37: =E10+E19+E28 -> 40341.667 | F37: =IF(B37=0,0,D37/B37-1) -> 0.053068065 | G37: =IF(C37=0,0,E37/C37-1) -> 0.050564236
A39: 기준 시즌 품목별 원가 구성 | C39: ="기준: "&설정!$C$15&" "&설정!$C$16&" / 비교: "&(설정!$C$15-1)&" "&설정!$C$16 -> 기준: 2026 FW / 비교: 2025 FW
A40: 품목 | B40: 원자재 | C40: 부자재 | D40: 가공임 | E40: 총원가 | F40: 원자재 비중 | G40: 부자재 비중 | H40: 가공임 비중 | I40: 전년 총원가 | J40: 전년대비 증감률
A41: =설정!$C$9 -> 아우터 | B41: =IFERROR(AVERAGEIFS(RawData!$F:$F,RawData!$A:$A,설정!$C$4,RawData!$B:$B,설정!$C$15,RawData!$C:$C,설정!$C$16,RawData!$D:$D,설정!$C$9),0) -> 62854.545 | C41: =IFERROR(AVERAGEIFS(RawData!$G:$G,RawData!$A:$A,설정!$C$4,RawData!$B:$B,설정!$C$15,RawData!$C:$C,설정!$C$16,RawData!$D:$D,설정!$C$9),0) -> 10690.909 | D41: =IFERROR(AVERAGEIFS(RawData!$H:$H,RawData!$A:$A,설정!$C$4,RawData!$B:$B,설정!$C$15,RawData!$C:$C,설정!$C$16,RawData!$D:$D,설정!$C$9),0) -> 30563.636 | E41: =SUM(B41:D41) -> 104109.09 | F41: =IF($E41=0,0,B41/$E41) -> 0.60373734 | G41: =IF($E41=0,0,C41/$E41) -> 0.10268949 | H41: =IF($E41=0,0,D41/$E41) -> 0.29357317 | I41: =IFERROR(AVERAGEIFS(RawData!$F:$F,RawData!$A:$A,설정!$C$4,RawData!$B:$B,(설정!$C$15-1),RawData!$C:$C,설정!$C$16,RawData!$D:$D,설정!$C$9),0)+IFERROR(AVERAGEIFS(RawData!$G:$G,RawData!$A:$A,설정!$C$4,RawData!$B:$B,(설정!$C$15-1),RawData!$C:$C,설정!$C$16,RawData!$D:$D,설정!$C$9),0)+IFERROR(AVERAGEIFS(RawData!$H:$H,RawData!$A:$A,설정!$C$4,RawData!$B:$B,(설정!$C$15-1),RawData!$C:$C,설정!$C$16,RawData!$D:$D,설정!$C$9),0) -> 96455.556 | J41: =IF(I41=0,0,E41/I41-1) -> 0.079347792
A42: =설정!$C$10 -> 니트 | B42: =IFERROR(AVERAGEIFS(RawData!$F:$F,RawData!$A:$A,설정!$C$4,RawData!$B:$B,설정!$C$15,RawData!$C:$C,설정!$C$16,RawData!$D:$D,설정!$C$10),0) -> 24177.778 | C42: =IFERROR(AVERAGEIFS(RawData!$G:$G,RawData!$A:$A,설정!$C$4,RawData!$B:$B,설정!$C$15,RawData!$C:$C,설정!$C$16,RawData!$D:$D,설정!$C$10),0) -> 3666.6667 | D42: =IFERROR(AVERAGEIFS(RawData!$H:$H,RawData!$A:$A,설정!$C$4,RawData!$B:$B,설정!$C$15,RawData!$C:$C,설정!$C$16,RawData!$D:$D,설정!$C$10),0) -> 13000 | E42: =SUM(B42:D42) -> 40844.444 | F42: =IF($E42=0,0,B42/$E42) -> 0.59194777 | G42: =IF($E42=0,0,C42/$E42) -> 0.089771491 | H42: =IF($E42=0,0,D42/$E42) -> 0.31828074 | I42: =IFERROR(AVERAGEIFS(RawData!$F:$F,RawData!$A:$A,설정!$C$4,RawData!$B:$B,(설정!$C$15-1),RawData!$C:$C,설정!$C$16,RawData!$D:$D,설정!$C$10),0)+IFERROR(AVERAGEIFS(RawData!$G:$G,RawData!$A:$A,설정!$C$4,RawData!$B:$B,(설정!$C$15-1),RawData!$C:$C,설정!$C$16,RawData!$D:$D,설정!$C$10),0)+IFERROR(AVERAGEIFS(RawData!$H:$H,RawData!$A:$A,설정!$C$4,RawData!$B:$B,(설정!$C$15-1),RawData!$C:$C,설정!$C$16,RawData!$D:$D,설정!$C$10),0) -> 38991.667 | J42: =IF(I42=0,0,E42/I42-1) -> 0.047517276
A43: =설정!$C$11 -> 셔츠 | B43: =IFERROR(AVERAGEIFS(RawData!$F:$F,RawData!$A:$A,설정!$C$4,RawData!$B:$B,설정!$C$15,RawData!$C:$C,설정!$C$16,RawData!$D:$D,설정!$C$11),0) -> 13450 | C43: =IFERROR(AVERAGEIFS(RawData!$G:$G,RawData!$A:$A,설정!$C$4,RawData!$B:$B,설정!$C$15,RawData!$C:$C,설정!$C$16,RawData!$D:$D,설정!$C$11),0) -> 3200 | D43: =IFERROR(AVERAGEIFS(RawData!$H:$H,RawData!$A:$A,설정!$C$4,RawData!$B:$B,설정!$C$15,RawData!$C:$C,설정!$C$16,RawData!$D:$D,설정!$C$11),0) -> 8662.5 | E43: =SUM(B43:D43) -> 25312.5 | F43: =IF($E43=0,0,B43/$E43) -> 0.53135802 | G43: =IF($E43=0,0,C43/$E43) -> 0.12641975 | H43: =IF($E43=0,0,D43/$E43) -> 0.34222222 | I43: =IFERROR(AVERAGEIFS(RawData!$F:$F,RawData!$A:$A,설정!$C$4,RawData!$B:$B,(설정!$C$15-1),RawData!$C:$C,설정!$C$16,RawData!$D:$D,설정!$C$11),0)+IFERROR(AVERAGEIFS(RawData!$G:$G,RawData!$A:$A,설정!$C$4,RawData!$B:$B,(설정!$C$15-1),RawData!$C:$C,설정!$C$16,RawData!$D:$D,설정!$C$11),0)+IFERROR(AVERAGEIFS(RawData!$H:$H,RawData!$A:$A,설정!$C$4,RawData!$B:$B,(설정!$C$15-1),RawData!$C:$C,설정!$C$16,RawData!$D:$D,설정!$C$11),0) -> 23955.556 | J43: =IF(I43=0,0,E43/I43-1) -> 0.056644249
A44: =설정!$C$12 -> 팬츠 | B44: =IFERROR(AVERAGEIFS(RawData!$F:$F,RawData!$A:$A,설정!$C$4,RawData!$B:$B,설정!$C$15,RawData!$C:$C,설정!$C$16,RawData!$D:$D,설정!$C$12),0) -> 16700 | C44: =IFERROR(AVERAGEIFS(RawData!$G:$G,RawData!$A:$A,설정!$C$4,RawData!$B:$B,설정!$C$15,RawData!$C:$C,설정!$C$16,RawData!$D:$D,설정!$C$12),0) -> 4244.4444 | D44: =IFERROR(AVERAGEIFS(RawData!$H:$H,RawData!$A:$A,설정!$C$4,RawData!$B:$B,설정!$C$15,RawData!$C:$C,설정!$C$16,RawData!$D:$D,설정!$C$12),0) -> 9933.3333 | E44: =SUM(B44:D44) -> 30877.778 | F44: =IF($E44=0,0,B44/$E44) -> 0.54084203 | G44: =IF($E44=0,0,C44/$E44) -> 0.13745952 | H44: =IF($E44=0,0,D44/$E44) -> 0.32169845 | I44: =IFERROR(AVERAGEIFS(RawData!$F:$F,RawData!$A:$A,설정!$C$4,RawData!$B:$B,(설정!$C$15-1),RawData!$C:$C,설정!$C$16,RawData!$D:$D,설정!$C$12),0)+IFERROR(AVERAGEIFS(RawData!$G:$G,RawData!$A:$A,설정!$C$4,RawData!$B:$B,(설정!$C$15-1),RawData!$C:$C,설정!$C$16,RawData!$D:$D,설정!$C$12),0)+IFERROR(AVERAGEIFS(RawData!$H:$H,RawData!$A:$A,설정!$C$4,RawData!$B:$B,(설정!$C$15-1),RawData!$C:$C,설정!$C$16,RawData!$D:$D,설정!$C$12),0) -> 29460 | J44: =IF(I44=0,0,E44/I44-1) -> 0.048125519
A45: =설정!$C$13 -> 스커트 | B45: =IFERROR(AVERAGEIFS(RawData!$F:$F,RawData!$A:$A,설정!$C$4,RawData!$B:$B,설정!$C$15,RawData!$C:$C,설정!$C$16,RawData!$D:$D,설정!$C$13),0) -> 13512.5 | C45: =IFERROR(AVERAGEIFS(RawData!$G:$G,RawData!$A:$A,설정!$C$4,RawData!$B:$B,설정!$C$15,RawData!$C:$C,설정!$C$16,RawData!$D:$D,설정!$C$13),0) -> 3625 | D45: =IFERROR(AVERAGEIFS(RawData!$H:$H,RawData!$A:$A,설정!$C$4,RawData!$B:$B,설정!$C$15,RawData!$C:$C,설정!$C$16,RawData!$D:$D,설정!$C$13),0) -> 8925 | E45: =SUM(B45:D45) -> 26062.5 | F45: =IF($E45=0,0,B45/$E45) -> 0.51846523 | G45: =IF($E45=0,0,C45/$E45) -> 0.13908873 | H45: =IF($E45=0,0,D45/$E45) -> 0.34244604 | I45: =IFERROR(AVERAGEIFS(RawData!$F:$F,RawData!$A:$A,설정!$C$4,RawData!$B:$B,(설정!$C$15-1),RawData!$C:$C,설정!$C$16,RawData!$D:$D,설정!$C$13),0)+IFERROR(AVERAGEIFS(RawData!$G:$G,RawData!$A:$A,설정!$C$4,RawData!$B:$B,(설정!$C$15-1),RawData!$C:$C,설정!$C$16,RawData!$D:$D,설정!$C$13),0)+IFERROR(AVERAGEIFS(RawData!$H:$H,RawData!$A:$A,설정!$C$4,RawData!$B:$B,(설정!$C$15-1),RawData!$C:$C,설정!$C$16,RawData!$D:$D,설정!$C$13),0) -> 25700 | J45: =IF(I45=0,0,E45/I45-1) -> 0.014105058
...
